Workbook

Sheet Sheet1
A1: Concentration (uM) | B1: rep1 | C1: rep2 | D1: rep3 | E1: Cell lines | F1: Run | G1: meanZero | H1: Concentration | I1: rep1 | J1: rep2 | K1: rep3 | L1: Cell lines | M1: Run | O1: Concentration | P1: rep1 | Q1: rep2 | R1: rep3 | S1: Cell lines | T1: Run | V1: Concentration | W1: rep1 | X1: rep2 | Y1: rep3 | Z1: Cell lines | AA1: Run | AD1: Concentration | AE1: rep1 | AF1: rep2 | AG1: rep3 | AH1: Cell lines | AI1: Run
A2: 50 | B2: 0 | C2: 362 | D2: 333 | E2: SNU1 C12 | F2: 1 | H2: 5 | I2: 1028 | J2: 1269 | K2: 1166 | L2: SNU1 C12 | M2: 2 | O2: 5 | P2: 553 | Q2: 540 | R2: 459 | S2: SNU1 C12 | T2: 3 | V2: 3 | W2: 901 | X2: 854 | Y2: 1087 | Z2: SNU1 C12 | AA2: 4 | AD2: 3 | AE2: 2678 | AF2: 2543 | AG2: 2396 | AH2: SNU1 C12 | AI2: 5
A3: 12.5 | B3: 0 | C3: 1201 | D3: 947 | E3: SNU1 C12 | F3: 1 | H3: 1.25 | I3: 1657 | J3: 1653 | K3: 1581 | L3: SNU1 C12 | M3: 2 | O3: 1.6666667 | P3: 615 | Q3: 572 | R3: 609 | S3: SNU1 C12 | T3: 3 | V3: 1 | W3: 814 | X3: 912 | Y3: 973 | Z3: SNU1 C12 | AA3: 4 | AD3: 0.68181818 | AE3: 4042 | AF3: 4194 | AG3: 4154 | AH3: SNU1 C12 | AI3: 5
A4: 3.125 | B4: 1286 | C4: 1263 | D4: 1124 | E4: SNU1 C12 | F4: 1 | H4: 0.3125 | I4: 6359 | J4: 7161 | K4: 5534 | L4: SNU1 C12 | M4: 2 | O4: 0.55555556 | P4: 1061 | Q4: 421 | R4: 831 | S4: SNU1 C12 | T4: 3 | V4: 0.33333333 | W4: 3694 | X4: 3817 | Y4: 3562 | Z4: SNU1 C12 | AA4: 4 | AD4: 0.15495868 | AE4: 13711 | AF4: 12595 | AG4: 13209 | AH4: SNU1 C12 | AI4: 5
A5: 0.78125 | B5: 1225 | C5: 1424 | D5: 1281 | E5: SNU1 C12 | F5: 1 | H5: 0.078125 | I5: 13926 | J5: 16713 | K5: 15658 | L5: SNU1 C12 | M5: 2 | O5: 0.18518519 | P5: 2590 | Q5: 4596 | R5: 5709 | S5: SNU1 C12 | T5: 3 | V5: 0.11111111 | W5: 5204 | X5: 4680 | Y5: 5588 | Z5: SNU1 C12 | AA5: 4 | AD5: 0.035217881 | AE5: 13445 | AF5: 15500 | AG5: 14232 | AH5: SNU1 C12 | AI5: 5
A6: 0.1953125 | B6: 4800 | C6: 5238 | D6: 3943 | E6: SNU1 C12 | F6: 1 | H6: 0.01953125 | I6: 18115 | J6: 16919 | K6: 18145 | L6: SNU1 C12 | M6: 2 | O6: 0.061728395 | P6: 6490 | Q6: 5095 | R6: 6743 | S6: SNU1 C12 | T6: 3 | V6: 0.037037037 | W6: 5058 | X6: 5438 | Y6: 5890 | Z6: SNU1 C12 | AA6: 4 | AD6: 0.008004064 | AE6: 14005 | AF6: 15270 | AG6: 15698 | AH6: SNU1 C12 | AI6: 5
A7: 0.048828125 | B7: 8878 | C7: 7774 | D7: 6913 | E7: SNU1 C12 | F7: 1 | H7: 0.004882813 | I7: 18512 | J7: 18254 | K7: 17247 | L7: SNU1 C12 | M7: 2 | O7: 0.020576132 | P7: 5350 | Q7: 8200 | R7: 7843 | S7: SNU1 C12 | T7: 3 | V7: 0.012345679 | W7: 7049 | X7: 7330 | Y7: 7434 | Z7: SNU1 C12 | AA7: 4 | AD7: 0.001819105 | AE7: 17193 | AF7: 17069 | AG7: 14344 | AH7: SNU1 C12 | AI7: 5
A8: 0.012207031 | B8: 6075 | C8: 5950 | D8: 5426 | E8: SNU1 C12 | F8: 1 | H8: 0.001220703 | I8: 22537 | J8: 19178 | K8: 18581 | L8: SNU1 C12 | M8: 2 | O8: 0.006858711 | P8: 9320 | Q8: 9932 | R8: 10739 | S8: SNU1 C12 | T8: 3 | V8: 0.0041152263 | W8: 7834 | X8: 7636 | Y8: 7962 | Z8: SNU1 C12 | AA8: 4 | AD8: 0.000413433 | AE8: 21190 | AF8: 17662 | AG8: 17752 | AH8: SNU1 C12 | AI8: 5
A9: 0 | B9: 12262 | C9: 16010 | D9: 15483 | E9: SNU1 C12 | F9: 1 | G9: =AVERAGE(B9:D9) -> 14585 | H9: 0 | I9: 26694 | J9: 25548 | K9: 23683 | L9: SNU1 C12 | M9: 2 | O9: 0 | P9: 13522 | Q9: 14060 | R9: 13770 | S9: SNU1 C12 | T9: 3 | V9: 0 | W9: 9848 | X9: 9934 | Y9: 10636 | Z9: SNU1 C12 | AA9: 4 | AD9: 0 | AE9: 20283 | AF9: 20031 | AG9: 18690 | AH9: SNU1 C12 | AI9: 5
A10: 50 | B10: 981 | C10: 776 | D10: 770 | E10: SNU1 C13 | F10: 1 | H10: 5 | I10: 406 | J10: 331 | K10: 352 | L10: SNU1 C13 | M10: 2 | O10: 5 | P10: 391 | Q10: 427 | R10: 276 | S10: SNU1 C13 | T10: 3 | V10: 3 | W10: 1370 | X10: 1434 | Y10: 1326 | Z10: SNU1 C13 | AA10: 4 | AD10: 3 | AE10: 1184 | AF10: 1206 | AG10: 1196 | AH10: SNU1 C13 | AI10: 5
A11: 12.5 | B11: 1086 | C11: 971 | D11: 1017 | E11: SNU1 C13 | F11: 1 | H11: 1.25 | I11: 933 | J11: 942 | K11: 915 | L11: SNU1 C13 | M11: 2 | O11: 1.6666667 | P11: 728 | Q11: 914 | R11: 839 | S11: SNU1 C13 | T11: 3 | V11: 1 | W11: 1614 | X11: 1485 | Y11: 1520 | Z11: SNU1 C13 | AA11: 4 | AD11: 0.68181818 | AE11: 2297 | AF11: 2495 | AG11: 2276 | AH11: SNU1 C13 | AI11: 5
A12: 3.125 | B12: 577 | C12: 473 | D12: 523 | E12: SNU1 C13 | F12: 1 | H12: 0.3125 | I12: 10460 | J12: 8646 | K12: 9217 | L12: SNU1 C13 | M12: 2 | O12: 0.55555556 | P12: 3266 | Q12: 3212 | R12: 2001 | S12: SNU1 C13 | T12: 3 | V12: 0.33333333 | W12: 10249 | X12: 8984 | Y12: 9544 | Z12: SNU1 C13 | AA12: 4 | AD12: 0.15495868 | AE12: 10820 | AF12: 9458 | AG12: 9561 | AH12: SNU1 C13 | AI12: 5
A13: 0.78125 | B13: 699 | C13: 905 | D13: 869 | E13: SNU1 C13 | F13: 1 | H13: 0.078125 | I13: 17411 | J13: 18010 | K13: 17080 | L13: SNU1 C13 | M13: 2 | O13: 0.18518519 | P13: 15523 | Q13: 11620 | R13: 3466 | S13: SNU1 C13 | T13: 3 | V13: 0.11111111 | W13: 14409 | X13: 14024 | Y13: 14549 | Z13: SNU1 C13 | AA13: 4 | AD13: 0.035217881 | AE13: 11327 | AF13: 9819 | AG13: 11278 | AH13: SNU1 C13 | AI13: 5
A14: 0.1953125 | B14: 5778 | C14: 4011 | D14: 5749 | E14: SNU1 C13 | F14: 1 | H14: 0.01953125 | I14: 14672 | J14: 15256 | K14: 12698 | L14: SNU1 C13 | M14: 2 | O14: 0.061728395 | P14: 15771 | Q14: 13965 | R14: 10773 | S14: SNU1 C13 | T14: 3 | V14: 0.037037037 | W14: 15842 | X14: 13583 | Y14: 13469 | Z14: SNU1 C13 | AA14: 4 | AD14: 0.008004064 | AE14: 11964 | AF14: 10471 | AG14: 10870 | AH14: SNU1 C13 | AI14: 5
A15: 0.048828125 | B15: 9880 | C15: 10945 | D15: 7419 | E15: SNU1 C13 | F15: 1 | H15: 0.004882813 | I15: 13005 | J15: 17149 | K15: 13749 | L15: SNU1 C13 | M15: 2 | O15: 0.020576132 | P15: 14099 | Q15: 11930 | R15: 12914 | S15: SNU1 C13 | T15: 3 | V15: 0.012345679 | W15: 16058 | X15: 14288 | Y15: 15981 | Z15: SNU1 C13 | AA15: 4 | AD15: 0.001819105 | AE15: 11926 | AF15: 9967 | AG15: 11734 | AH15: SNU1 C13 | AI15: 5
A16: 0.012207031 | B16: 12614 | C16: 11176 | D16: 10635 | E16: SNU1 C13 | F16: 1 | H16: 0.001220703 | I16: 15728 | J16: 12729 | K16: 15213 | L16: SNU1 C13 | M16: 2 | O16: 0.006858711 | P16: 19059 | Q16: 4419 | R16: 2227 | S16: SNU1 C13 | T16: 3 | V16: 0.0041152263 | W16: 16716 | X16: 17064 | Y16: 14974 | Z16: SNU1 C13 | AA16: 4 | AD16: 0.000413433 | AE16: 11719 | AF16: 10974 | AG16: 13535 | AH16: SNU1 C13 | AI16: 5
A17: 0 | B17: 21857 | C17: 14764 | D17: 12377 | E17: SNU1 C13 | F17: 1 | G17: =AVERAGE(B17:D17) -> 16332.667 | H17: 0 | I17: 13016 | J17: 12110 | K17: 12816 | L17: SNU1 C13 | M17: 2 | O17: 0 | P17: 16057 | Q17: 15018 | R17: 9035 | S17: SNU1 C13 | T17: 3 | V17: 0 | W17: 15345 | X17: 16967 | Y17: 17731 | Z17: SNU1 C13 | AA17: 4 | AD17: 0 | AE17: 10991 | AF17: 11611 | AG17: 10701 | AH17: SNU1 C13 | AI17: 5
A18: 50 | B18: 967 | C18: 942 | D18: 926 | E18: SNU1 C24 | F18: 1 | H18: 5 | I18: 1971 | J18: 2027 | K18: 2424 | L18: SNU1 C24 | M18: 2 | O18: 5 | P18: 641 | Q18: 637 | R18: 572 | S18: SNU1 C24 | T18: 3 | V18: 3 | W18: 1794 | X18: 1452 | Y18: 1582 | Z18: SNU1 C24 | AA18: 4 | AD18: 3 | AE18: 3125 | AF18: 3561 | AG18: 3603 | AH18: SNU1 C24 | AI18: 5
A19: 12.5 | B19: 925 | C19: 910 | D19: 684 | E19: SNU1 C24 | F19: 1 | H19: 1.25 | I19: 2393 | J19: 2506 | K19: 2439 | L19: SNU1 C24 | M19: 2 | O19: 1.6666667 | P19: 587 | Q19: 625 | R19: 550 | S19: SNU1 C24 | T19: 3 | V19: 1 | W19: 1475 | X19: 1395 | Y19: 1350 | Z19: SNU1 C24 | AA19: 4 | AD19: 0.68181818 | AE19: 3416 | AF19: 3518 | AG19: 3711 | AH19: SNU1 C24 | AI19: 5
A20: 3.125 | B20: 1027 | C20: 571 | D20: 635 | E20: SNU1 C24 | F20: 1 | H20: 0.3125 | I20: 4090 | J20: 3417 | K20: 4119 | L20: SNU1 C24 | M20: 2 | O20: 0.55555556 | P20: 543 | Q20: 501 | R20: 507 | S20: SNU1 C24 | T20: 3 | V20: 0.33333333 | W20: 2085 | X20: 2124 | Y20: 2372 | Z20: SNU1 C24 | AA20: 4 | AD20: 0.15495868 | AE20: 5227 | AF20: 4789 | AG20: 5601 | AH20: SNU1 C24 | AI20: 5
A21: 0.78125 | B21: 977 | C21: 740 | D21: 311 | E21: SNU1 C24 | F21: 1 | H21: 0.078125 | I21: 6135 | J21: 6050 | K21: 5680 | L21: SNU1 C24 | M21: 2 | O21: 0.18518519 | P21: 703 | Q21: 702 | R21: 854 | S21: SNU1 C24 | T21: 3 | V21: 0.11111111 | W21: 2862 | X21: 2552 | Y21: 2773 | Z21: SNU1 C24 | AA21: 4 | AD21: 0.035217881 | AE21: 6437 | AF21: 6674 | AG21: 5204 | AH21: SNU1 C24 | AI21: 5
A22: 0.1953125 | B22: 1577 | C22: 857 | D22: 1271 | E22: SNU1 C24 | F22: 1 | H22: 0.01953125 | I22: 6520 | J22: 5996 | K22: 6239 | L22: SNU1 C24 | M22: 2 | O22: 0.061728395 | P22: 1146 | Q22: 1045 | R22: 931 | S22: SNU1 C24 | T22: 3 | V22: 0.037037037 | W22: 5302 | X22: 2420 | Y22: 3269 | Z22: SNU1 C24 | AA22: 4 | AD22: 0.008004064 | AE22: 7718 | AF22: 6307 | AG22: 6030 | AH22: SNU1 C24 | AI22: 5
A23: 0.048828125 | B23: 2023 | C23: 1514 | D23: 1237 | E23: SNU1 C24 | F23: 1 | H23: 0.004882813 | I23: 8019 | J23: 7527 | K23: 6054 | L23: SNU1 C24 | M23: 2 | O23: 0.020576132 | P23: 1365 | Q23: 1449 | R23: 1299 | S23: SNU1 C24 | T23: 3 | V23: 0.012345679 | W23: 3968 | X23: 3569 | Y23: 3322 | Z23: SNU1 C24 | AA23: 4 | AD23: 0.001819105 | AE23: 8932 | AF23: 6842 | AG23: 6503 | AH23: SNU1 C24 | AI23: 5
A24: 0.012207031 | B24: 1431 | C24: 1354 | D24: 1074 | E24: SNU1 C24 | F24: 1 | H24: 0.001220703 | I24: 9813 | J24: 8453 | K24: 9290 | L24: SNU1 C24 | M24: 2 | O24: 0.006858711 | P24: 1843 | Q24: 2675 | R24: 2395 | S24: SNU1 C24 | T24: 3 | V24: 0.0041152263 | W24: 4615 | X24: 4243 | Y24: 3951 | Z24: SNU1 C24 | AA24: 4 | AD24: 0.000413433 | AE24: 10982 | AF24: 10628 | AG24: 8499 | AH24: SNU1 C24 | AI24: 5
A25: 0 | B25: 3497 | C25: 2264 | D25: 3953 | E25: SNU1 C24 | F25: 1 | G25: =AVERAGE(B25:D25) -> 3238 | H25: 0 | I25: 15172 | J25: 11870 | K25: 9675 | L25: SNU1 C24 | M25: 2 | O25: 0 | P25: 5163 | Q25: 4945 | R25: 4972 | S25: SNU1 C24 | T25: 3 | V25: 0 | W25: 9430 | X25: 8146 | Y25: 8723 | Z25: SNU1 C24 | AA25: 4 | AD25: 0 | AE25: 12464 | AF25: 12609 | AG25: 11664 | AH25: SNU1 C24 | AI25: 5
A26: 50 | B26: 119 | C26: 141 | D26: 148 | E26: SNU1 C111 | F26: 1 | H26: 5 | I26: 2043 | J26: 2119 | K26: 1908 | L26: SNU1 C111 | M26: 2 | V26: 3 | W26: 779 | X26: 675 | Y26: 654 | Z26: SNU1 C111 | AA26: 4 | AD26: 3 | AE26: 2965 | AF26: 2916 | AG26: 3085 | AH26: SNU1 C111 | AI26: 5
A27: 12.5 | B27: 437 | C27: 416 | D27: 469 | E27: SNU1 C111 | F27: 1 | H27: 1.25 | I27: 2291 | J27: 2021 | K27: 2230 | L27: SNU1 C111 | M27: 2 | V27: 1 | W27: 721 | X27: 722 | Y27: 954 | Z27: SNU1 C111 | AA27: 4 | AD27: 0.68181818 | AE27: 3356 | AF27: 3401 | AG27: 3420 | AH27: SNU1 C111 | AI27: 5
A28: 3.125 | B28: 103 | C28: 404 | D28: 219 | E28: SNU1 C111 | F28: 1 | H28: 0.3125 | I28: 7163 | J28: 6150 | K28: 6943 | L28: SNU1 C111 | M28: 2 | V28: 0.33333333 | W28: 1330 | X28: 1061 | Y28: 1338 | Z28: SNU1 C111 | AA28: 4 | AD28: 0.15495868 | AE28: 10452 | AF28: 9224 | AG28: 8294 | AH28: SNU1 C111 | AI28: 5
A29: 0.78125 | B29: 132 | C29: 72 | D29: 79 | E29: SNU1 C111 | F29: 1 | H29: 0.078125 | I29: 16376 | J29: 16034 | K29: 17807 | L29: SNU1 C111 | M29: 2 | V29: 0.11111111 | W29: 2234 | X29: 2041 | Y29: 1772 | Z29: SNU1 C111 | AA29: 4 | AD29: 0.035217881 | AE29: 11389 | AF29: 10481 | AG29: 11289 | AH29: SNU1 C111 | AI29: 5
A30: 0.1953125 | B30: 177 | C30: 214 | D30: 348 | E30: SNU1 C111 | F30: 1 | H30: 0.01953125 | I30: 18206 | J30: 19094 | K30: 16081 | L30: SNU1 C111 | M30: 2 | V30: 0.037037037 | W30: 2482 | X30: 2229 | Y30: 2041 | Z30: SNU1 C111 | AA30: 4 | AD30: 0.008004064 | AE30: 12904 | AF30: 11565 | AG30: 11137 | AH30: SNU1 C111 | AI30: 5
A31: 0.048828125 | B31: 2552 | C31: 816 | D31: 1642 | E31: SNU1 C111 | F31: 1 | H31: 0.004882813 | I31: 20664 | J31: 21230 | K31: 19708 | L31: SNU1 C111 | M31: 2 | V31: 0.012345679 | W31: 3363 | X31: 2963 | Y31: 2925 | Z31: SNU1 C111 | AA31: 4 | AD31: 0.001819105 | AE31: 12322 | AF31: 12088 | AG31: 11931 | AH31: SNU1 C111 | AI31: 5
A32: 0.012207031 | B32: 2777 | C32: 2454 | D32: 3191 | E32: SNU1 C111 | F32: 1 | H32: 0.001220703 | I32: 21801 | J32: 22720 | K32: 22949 | L32: SNU1 C111 | M32: 2 | V32: 0.0041152263 | W32: 2903 | X32: 3274 | Y32: 3258 | Z32: SNU1 C111 | AA32: 4 | AD32: 0.000413433 | AE32: 15885 | AF32: 15120 | AG32: 14340 | AH32: SNU1 C111 | AI32: 5
A33: 0 | B33: 10953 | C33: 11532 | D33: 10974 | E33: SNU1 C111 | F33: 1 | G33: =AVERAGE(B33:D33) -> 11153 | H33: 0 | I33: 29584 | J33: 27002 | K33: 27903 | L33: SNU1 C111 | M33: 2 | V33: 0 | W33: 8448 | X33: 7545 | Y33: 8928 | Z33: SNU1 C111 | AA33: 4 | AD33: 0 | AE33: 21346 | AF33: 19705 | AG33: 18315 | AH33: SNU1 C111 | AI33: 5
A34: 50 | B34: 263 | C34: 272 | D34: 275 | E34: SNU1 C114 | F34: 1 | H34: 5 | I34: 2534 | J34: 2328 | K34: 2226 | L34: SNU1 C114 | M34: 2 | V34: 3 | W34: 917 | X34: 856 | Y34: 904 | Z34: SNU1 C114 | AA34: 4 | AD34: 3 | AE34: 2526 | AF34: 2591 | AG34: 2555 | AH34: SNU1 C114 | AI34: 5
A35: 12.5 | B35: 912 | C35: 1045 | D35: 1006 | E35: SNU1 C114 | F35: 1 | H35: 1.25 | I35: 2956 | J35: 3038 | K35: 2918 | L35: SNU1 C114 | M35: 2 | V35: 1 | W35: 898 | X35: 969 | Y35: 1073 | Z35: SNU1 C114 | AA35: 4 | AD35: 0.68181818 | AE35: 4817 | AF35: 4924 | AG35: 5042 | AH35: SNU1 C114 | AI35: 5
A36: 3.125 | B36: 1106 | C36: 1172 | D36: 1704 | E36: SNU1 C114 | F36: 1 | H36: 0.3125 | I36: 6814 | J36: 6340 | K36: 6859 | L36: SNU1 C114 | M36: 2 | V36: 0.33333333 | W36: 2430 | X36: 2179 | Y36: 2213 | Z36: SNU1 C114 | AA36: 4 | AD36: 0.15495868 | AE36: 8938 | AF36: 8273 | AG36: 10608 | AH36: SNU1 C114 | AI36: 5
A37: 0.78125 | B37: 1346 | C37: 1125 | D37: 1414 | E37: SNU1 C114 | F37: 1 | H37: 0.078125 | I37: 12048 | J37: 11571 | K37: 12608 | L37: SNU1 C114 | M37: 2 | V37: 0.11111111 | W37: 3320 | X37: 3798 | Y37: 3051 | Z37: SNU1 C114 | AA37: 4 | AD37: 0.035217881 | AE37: 8497 | AF37: 7733 | AG37: 10961 | AH37: SNU1 C114 | AI37: 5
A38: 0.1953125 | B38: 1123 | C38: 563 | D38: 3245 | E38: SNU1 C114 | F38: 1 | H38: 0.01953125 | I38: 13245 | J38: 11763 | K38: 12668 | L38: SNU1 C114 | M38: 2 | V38: 0.037037037 | W38: 3815 | X38: 4429 | Y38: 3905 | Z38: SNU1 C114 | AA38: 4 | AD38: 0.008004064 | AE38: 7933 | AF38: 7168 | AG38: 7270 | AH38: SNU1 C114 | AI38: 5
A39: 0.048828125 | B39: 4349 | C39: 3769 | D39: 4713 | E39: SNU1 C114 | F39: 1 | H39: 0.004882813 | I39: 12085 | J39: 12402 | K39: 12741 | L39: SNU1 C114 | M39: 2 | V39: 0.012345679 | W39: 4752 | X39: 4600 | Y39: 4591 | Z39: SNU1 C114 | AA39: 4 | AD39: 0.001819105 | AE39: 6392 | AF39: 6203 | AG39: 7820 | AH39: SNU1 C114 | AI39: 5
A40: 0.012207031 | B40: 4916 | C40: 4818 | D40: 5479 | E40: SNU1 C114 | F40: 1 | H40: 0.001220703 | I40: 13082 | J40: 13373 | K40: 14799 | L40: SNU1 C114 | M40: 2 | V40: 0.0041152263 | W40: 4378 | X40: 4977 | Y40: 4746 | Z40: SNU1 C114 | AA40: 4 | AD40: 0.000413433 | AE40: 7234 | AF40: 8956 | AG40: 8689 | AH40: SNU1 C114 | AI40: 5
...

Sheet Sheet2
A1: Concentration (nM) | B1: Count | C1: Cell line | D1: Run
A2: 50000 | B2: 0 | C2: SNU1 C12 | D2: 1
A3: 12500 | B3: 0 | C3: SNU1 C12 | D3: 1
A4: 3125 | B4: 1286 | C4: SNU1 C12 | D4: 1
A5: 781.25 | B5: 1225 | C5: SNU1 C12 | D5: 1
A6: 195.3125 | B6: 4800 | C6: SNU1 C12 | D6: 1
A7: 48.828125 | B7: 8878 | C7: SNU1 C12 | D7: 1
A8: 12.207031 | B8: 6075 | C8: SNU1 C12 | D8: 1
A9: 0 | B9: 12262 | C9: SNU1 C12 | D9: 1
A10: 50000 | B10: 981 | C10: SNU1 C13 | D10: 1
A11: 12500 | B11: 1086 | C11: SNU1 C13 | D11: 1
A12: 3125 | B12: 577 | C12: SNU1 C13 | D12: 1
A13: 781.25 | B13: 699 | C13: SNU1 C13 | D13: 1
... A553: 0 | B553: 9745 | C553: SNU1 C114 | D553: 5

Sheet Sheet3
A1: Concentration (nM) | B1: rep1 | C1: rep2 | D1: rep3 | E1: Cell lines | F1: Run | H1: Concentration (nM) | I1: rep1 | J1: rep2 | K1: rep3 | L1: Cell lines | M1: Run | N1: Concentration (nM) | O1: rep1 | P1: rep2 | Q1: rep3 | R1: Cell lines | S1: Run
A2: 50000 | B2: =Sheet1!B2/Sheet1!$G$9 -> 0 | C2: =Sheet1!C2/Sheet1!$G$9 -> 0.024820021 | D2: =Sheet1!D2/Sheet1!$G$9 -> 0.022831676 | E2: SNU1 C12 | F2: 1 | H2: 50000 | I2: 0 | J2: 0.024820021 | K2: 0.022831676 | L2: SNU1 C12 | M2: 1 | N2: 50000 | O2: =Sheet1!P2/Sheet1!$G$9 -> 0.037915667 | P2: =Sheet1!Q2/Sheet1!$G$9 -> 0.03702434 | Q2: =Sheet1!R2/Sheet1!$G$9 -> 0.031470689 | R2: SNU1 C12 | S2: 1
A3: 12500 | B3: =Sheet1!B3/Sheet1!$G$9 -> 0 | C3: =Sheet1!C3/Sheet1!$G$9 -> 0.082344875 | D3: =Sheet1!D3/Sheet1!$G$9 -> 0.064929722 | E3: SNU1 C12 | F3: 1 | H3: 12500 | I3: 0 | J3: 0.082344875 | K3: 0.064929722 | L3: SNU1 C12 | M3: 1 | N3: 12500 | O3: =Sheet1!P3/Sheet1!$G$9 -> 0.04216661 | P3: =Sheet1!Q3/Sheet1!$G$9 -> 0.039218375 | Q3: =Sheet1!R3/Sheet1!$G$9 -> 0.041755228 | R3: SNU1 C12 | S3: 1
A4: 3125 | B4: =Sheet1!B4/Sheet1!$G$9 -> 0.08817278 | C4: =Sheet1!C4/Sheet1!$G$9 -> 0.086595818 | D4: =Sheet1!D4/Sheet1!$G$9 -> 0.077065478 | E4: SNU1 C12 | F4: 1 | H4: 3125 | I4: 0.08817278 | J4: 0.086595818 | K4: 0.077065478 | L4: SNU1 C12 | M4: 1 | N4: 3125 | O4: =Sheet1!P4/Sheet1!$G$9 -> 0.072745972 | P4: =Sheet1!Q4/Sheet1!$G$9 -> 0.028865273 | Q4: =Sheet1!R4/Sheet1!$G$9 -> 0.056976346 | R4: SNU1 C12 | S4: 1
A5: 781.25 | B5: =Sheet1!B5/Sheet1!$G$9 -> 0.083990401 | C5: =Sheet1!C5/Sheet1!$G$9 -> 0.097634556 | D5: =Sheet1!D5/Sheet1!$G$9 -> 0.087829962 | E5: SNU1 C12 | F5: 1 | H5: 781.25 | I5: 0.083990401 | J5: 0.097634556 | K5: 0.087829962 | L5: SNU1 C12 | M5: 1 | N5: 781.25 | O5: =Sheet1!P5/Sheet1!$G$9 -> 0.17757971 | P5: =Sheet1!Q5/Sheet1!$G$9 -> 0.31511827 | Q5: =Sheet1!R5/Sheet1!$G$9 -> 0.39142955 | R5: SNU1 C12 | S5: 1
A6: 195.3125 | B6: =Sheet1!B6/Sheet1!$G$9 -> 0.32910525 | C6: =Sheet1!C6/Sheet1!$G$9 -> 0.3591361 | D6: =Sheet1!D6/Sheet1!$G$9 -> 0.27034625 | E6: SNU1 C12 | F6: 1 | H6: 195.3125 | I6: 0.32910525 | J6: 0.3591361 | K6: 0.27034625 | L6: SNU1 C12 | M6: 1 | N6: 195.3125 | O6: =Sheet1!P6/Sheet1!$G$9 -> 0.44497772 | P6: =Sheet1!Q6/Sheet1!$G$9 -> 0.3493315 | Q6: =Sheet1!R6/Sheet1!$G$9 -> 0.46232431 | R6: SNU1 C12 | S6: 1
A7: 48.828125 | B7: =Sheet1!B7/Sheet1!$G$9 -> 0.60870758 | C7: =Sheet1!C7/Sheet1!$G$9 -> 0.53301337 | D7: =Sheet1!D7/Sheet1!$G$9 -> 0.47398012 | E7: SNU1 C12 | F7: 1 | H7: 48.828125 | I7: 0.60870758 | J7: 0.53301337 | K7: 0.47398012 | L7: SNU1 C12 | M7: 1 | N7: 48.828125 | O7: =Sheet1!P7/Sheet1!$G$9 -> 0.36681522 | P7: =Sheet1!Q7/Sheet1!$G$9 -> 0.56222146 | Q7: =Sheet1!R7/Sheet1!$G$9 -> 0.53774426 | R7: SNU1 C12 | S7: 1
A8: 12.207031 | B8: =Sheet1!B8/Sheet1!$G$9 -> 0.41652383 | C8: =Sheet1!C8/Sheet1!$G$9 -> 0.40795338 | D8: =Sheet1!D8/Sheet1!$G$9 -> 0.37202605 | E8: SNU1 C12 | F8: 1 | H8: 12.207031 | I8: 0.41652383 | J8: 0.40795338 | K8: 0.37202605 | L8: SNU1 C12 | M8: 1 | N8: 12.207031 | O8: =Sheet1!P8/Sheet1!$G$9 -> 0.63901268 | P8: =Sheet1!Q8/Sheet1!$G$9 -> 0.6809736 | Q8: =Sheet1!R8/Sheet1!$G$9 -> 0.73630442 | R8: SNU1 C12 | S8: 1
A9: 0 | B9: =Sheet1!B9/Sheet1!$G$9 -> 0.84072677 | C9: =Sheet1!C9/Sheet1!$G$9 -> 1.0977031 | D9: =Sheet1!D9/Sheet1!$G$9 -> 1.0615701 | E9: SNU1 C12 | F9: 1 | H9: 0 | I9: 0.84072677 | J9: 1.0977031 | K9: 1.0615701 | L9: SNU1 C12 | M9: 1 | N9: 0 | O9: =Sheet1!P9/Sheet1!$G$9 -> 0.9271169 | P9: =Sheet1!Q9/Sheet1!$G$9 -> 0.96400411 | Q9: =Sheet1!R9/Sheet1!$G$9 -> 0.94412067 | R9: SNU1 C12 | S9: 1
A10: 50000 | B10: =Sheet1!B10/Sheet1!$G$17 -> 0.060063676 | C10: =Sheet1!C10/Sheet1!$G$17 -> 0.047512143 | D10: =Sheet1!D10/Sheet1!$G$17 -> 0.047144781 | E10: SNU1 C13 | F10: 1 | H10: 50000 | I10: 0.060063676 | J10: 0.047512143 | K10: 0.047144781 | L10: SNU1 C13 | M10: 1 | N10: 50000 | O10: =Sheet1!P10/Sheet1!$G$17 -> 0.023939753 | P10: =Sheet1!Q10/Sheet1!$G$17 -> 0.026143924 | Q10: =Sheet1!R10/Sheet1!$G$17 -> 0.016898649 | R10: SNU1 C13 | S10: 1
A11: 12500 | B11: =Sheet1!B11/Sheet1!$G$17 -> 0.06649251 | C11: =Sheet1!C11/Sheet1!$G$17 -> 0.059451406 | D11: =Sheet1!D11/Sheet1!$G$17 -> 0.062267848 | E11: SNU1 C13 | F11: 1 | H11: 12500 | I11: 0.06649251 | J11: 0.059451406 | K11: 0.062267848 | L11: SNU1 C13 | M11: 1 | N11: 12500 | O11: =Sheet1!P11/Sheet1!$G$17 -> 0.044573248 | P11: =Sheet1!Q11/Sheet1!$G$17 -> 0.055961468 | Q11: =Sheet1!R11/Sheet1!$G$17 -> 0.051369444 | R11: SNU1 C13 | S11: 1
A12: 3125 | B12: =Sheet1!B12/Sheet1!$G$17 -> 0.035327973 | C12: =Sheet1!C12/Sheet1!$G$17 -> 0.028960366 | D12: =Sheet1!D12/Sheet1!$G$17 -> 0.032021715 | E12: SNU1 C13 | F12: 1 | H12: 3125 | I12: 0.035327973 | J12: 0.028960366 | K12: 0.032021715 | L12: SNU1 C13 | M12: 1 | N12: 3125 | O12: =Sheet1!P12/Sheet1!$G$17 -> 0.19996735 | P12: =Sheet1!Q12/Sheet1!$G$17 -> 0.19666109 | Q12: =Sheet1!R12/Sheet1!$G$17 -> 0.1225152 | R12: SNU1 C13 | S12: 1
A13: 781.25 | B13: =Sheet1!B13/Sheet1!$G$17 -> 0.042797665 | C13: =Sheet1!C13/Sheet1!$G$17 -> 0.055410425 | D13: =Sheet1!D13/Sheet1!$G$17 -> 0.053206253 | E13: SNU1 C13 | F13: 1 | H13: 781.25 | I13: 0.042797665 | J13: 0.055410425 | K13: 0.053206253 | L13: SNU1 C13 | M13: 1 | N13: 781.25 | O13: =Sheet1!P13/Sheet1!$G$17 -> 0.95042655 | P13: =Sheet1!Q13/Sheet1!$G$17 -> 0.71145761 | Q13: =Sheet1!R13/Sheet1!$G$17 -> 0.21221274 | R13: SNU1 C13 | S13: 1
A14: 195.3125 | B14: =Sheet1!B14/Sheet1!$G$17 -> 0.35376954 | C14: =Sheet1!C14/Sheet1!$G$17 -> 0.24558145 | D14: =Sheet1!D14/Sheet1!$G$17 -> 0.35199396 | E14: SNU1 C13 | F14: 1 | H14: 195.3125 | I14: 0.35376954 | J14: 0.24558145 | K14: 0.35199396 | L14: SNU1 C13 | M14: 1 | N14: 195.3125 | O14: =Sheet1!P14/Sheet1!$G$17 -> 0.96561084 | P14: =Sheet1!Q14/Sheet1!$G$17 -> 0.8550349 | Q14: =Sheet1!R14/Sheet1!$G$17 -> 0.65959835 | R14: SNU1 C13 | S14: 1
A15: 48.828125 | B15: =Sheet1!B15/Sheet1!$G$17 -> 0.60492265 | C15: =Sheet1!C15/Sheet1!$G$17 -> 0.67012939 | D15: =Sheet1!D15/Sheet1!$G$17 -> 0.45424303 | E15: SNU1 C13 | F15: 1 | H15: 48.828125 | I15: 0.60492265 | J15: 0.67012939 | K15: 0.45424303 | L15: SNU1 C13 | M15: 1 | N15: 48.828125 | O15: =Sheet1!P15/Sheet1!$G$17 -> 0.86323932 | P15: =Sheet1!Q15/Sheet1!$G$17 -> 0.73043798 | Q15: =Sheet1!R15/Sheet1!$G$17 -> 0.79068533 | R15: SNU1 C13 | S15: 1
A16: 12.207031 | B16: =Sheet1!B16/Sheet1!$G$17 -> 0.77231724 | C16: =Sheet1!C16/Sheet1!$G$17 -> 0.68427283 | D16: =Sheet1!D16/Sheet1!$G$17 -> 0.65114903 | E16: SNU1 C13 | F16: 1 | H16: 12.207031 | I16: 0.77231724 | J16: 0.68427283 | K16: 0.65114903 | L16: SNU1 C13 | M16: 1 | N16: 12.207031 | O16: =Sheet1!P16/Sheet1!$G$17 -> 1.1669252 | P16: =Sheet1!Q16/Sheet1!$G$17 -> 0.27056206 | Q16: =Sheet1!R16/Sheet1!$G$17 -> 0.1363525 | R16: SNU1 C13 | S16: 1
A17: 0 | B17: =Sheet1!B17/Sheet1!$G$17 -> 1.3382383 | C17: =Sheet1!C17/Sheet1!$G$17 -> 0.90395526 | D17: =Sheet1!D17/Sheet1!$G$17 -> 0.75780644 | E17: SNU1 C13 | F17: 1 | H17: 0 | I17: 1.3382383 | J17: 0.90395526 | K17: 0.75780644 | L17: SNU1 C13 | M17: 1 | N17: 0 | O17: =Sheet1!P17/Sheet1!$G$17 -> 0.98312176 | P17: =Sheet1!Q17/Sheet1!$G$17 -> 0.91950692 | Q17: =Sheet1!R17/Sheet1!$G$17 -> 0.55318584 | R17: SNU1 C13 | S17: 1
A18: 50000 | B18: =Sheet1!B18/Sheet1!$G$25 -> 0.29864114 | C18: =Sheet1!C18/Sheet1!$G$25 -> 0.29092032 | D18: =Sheet1!D18/Sheet1!$G$25 -> 0.285979 | E18: SNU1 C24 | F18: 1 | H18: 50000 | I18: 0.29864114 | J18: 0.29092032 | K18: 0.285979 | L18: SNU1 C24 | M18: 1 | N18: 50000 | O18: =Sheet1!P18/Sheet1!$G$25 -> 0.1979617 | P18: =Sheet1!Q18/Sheet1!$G$25 -> 0.19672637 | Q18: =Sheet1!R18/Sheet1!$G$25 -> 0.17665225 | R18: SNU1 C24 | S18: 1
A19: 12500 | B19: =Sheet1!B19/Sheet1!$G$25 -> 0.28567017 | C19: =Sheet1!C19/Sheet1!$G$25 -> 0.28103768 | D19: =Sheet1!D19/Sheet1!$G$25 -> 0.21124151 | E19: SNU1 C24 | F19: 1 | H19: 12500 | I19: 0.28567017 | J19: 0.28103768 | K19: 0.21124151 | L19: SNU1 C24 | M19: 1 | N19: 12500 | O19: =Sheet1!P19/Sheet1!$G$25 -> 0.18128474 | P19: =Sheet1!Q19/Sheet1!$G$25 -> 0.19302038 | Q19: =Sheet1!R19/Sheet1!$G$25 -> 0.16985794 | R19: SNU1 C24 | S19: 1
A20: 3125 | B20: =Sheet1!B20/Sheet1!$G$25 -> 0.31717109 | C20: =Sheet1!C20/Sheet1!$G$25 -> 0.17634342 | D20: =Sheet1!D20/Sheet1!$G$25 -> 0.19610871 | E20: SNU1 C24 | F20: 1 | H20: 3125 | I20: 0.31717109 | J20: 0.17634342 | K20: 0.19610871 | L20: SNU1 C24 | M20: 1 | N20: 3125 | O20: =Sheet1!P20/Sheet1!$G$25 -> 0.16769611 | P20: =Sheet1!Q20/Sheet1!$G$25 -> 0.15472514 | Q20: =Sheet1!R20/Sheet1!$G$25 -> 0.15657813 | R20: SNU1 C24 | S20: 1
A21: 781.25 | B21: =Sheet1!B21/Sheet1!$G$25 -> 0.30172946 | C21: =Sheet1!C21/Sheet1!$G$25 -> 0.22853613 | D21: =Sheet1!D21/Sheet1!$G$25 -> 0.096046943 | E21: SNU1 C24 | F21: 1 | H21: 781.25 | I21: 0.30172946 | J21: 0.22853613 | K21: 0.096046943 | L21: SNU1 C24 | M21: 1 | N21: 781.25 | O21: =Sheet1!P21/Sheet1!$G$25 -> 0.21710933 | P21: =Sheet1!Q21/Sheet1!$G$25 -> 0.21680049 | Q21: =Sheet1!R21/Sheet1!$G$25 -> 0.26374305 | R21: SNU1 C24 | S21: 1
A22: 195.3125 | B22: =Sheet1!B22/Sheet1!$G$25 -> 0.48702903 | C22: =Sheet1!C22/Sheet1!$G$25 -> 0.26466955 | D22: =Sheet1!D22/Sheet1!$G$25 -> 0.39252625 | E22: SNU1 C24 | F22: 1 | H22: 195.3125 | I22: 0.48702903 | J22: 0.26466955 | K22: 0.39252625 | L22: SNU1 C24 | M22: 1 | N22: 195.3125 | O22: =Sheet1!P22/Sheet1!$G$25 -> 0.35392217 | P22: =Sheet1!Q22/Sheet1!$G$25 -> 0.32273008 | Q22: =Sheet1!R22/Sheet1!$G$25 -> 0.28752316 | R22: SNU1 C24 | S22: 1
A23: 48.828125 | B23: =Sheet1!B23/Sheet1!$G$25 -> 0.62476838 | C23: =Sheet1!C23/Sheet1!$G$25 -> 0.46757258 | D23: =Sheet1!D23/Sheet1!$G$25 -> 0.38202594 | E23: SNU1 C24 | F23: 1 | H23: 48.828125 | I23: 0.62476838 | J23: 0.46757258 | K23: 0.38202594 | L23: SNU1 C24 | M23: 1 | N23: 48.828125 | O23: =Sheet1!P23/Sheet1!$G$25 -> 0.42155652 | P23: =Sheet1!Q23/Sheet1!$G$25 -> 0.44749846 | Q23: =Sheet1!R23/Sheet1!$G$25 -> 0.40117356 | R23: SNU1 C24 | S23: 1
A24: 12.207031 | B24: =Sheet1!B24/Sheet1!$G$25 -> 0.44193947 | C24: =Sheet1!C24/Sheet1!$G$25 -> 0.41815936 | D24: =Sheet1!D24/Sheet1!$G$25 -> 0.33168623 | E24: SNU1 C24 | F24: 1 | H24: 12.207031 | I24: 0.44193947 | J24: 0.41815936 | K24: 0.33168623 | L24: SNU1 C24 | M24: 1 | N24: 12.207031 | O24: =Sheet1!P24/Sheet1!$G$25 -> 0.56917851 | P24: =Sheet1!Q24/Sheet1!$G$25 -> 0.82612724 | Q24: =Sheet1!R24/Sheet1!$G$25 -> 0.73965411 | R24: SNU1 C24 | S24: 1
A25: 0 | B25: =Sheet1!B25/Sheet1!$G$25 -> 1.0799876 | C25: =Sheet1!C25/Sheet1!$G$25 -> 0.69919704 | D25: =Sheet1!D25/Sheet1!$G$25 -> 1.2208153 | E25: SNU1 C24 | F25: 1 | H25: 0 | I25: 1.0799876 | J25: 0.69919704 | K25: 1.2208153 | L25: SNU1 C24 | M25: 1 | N25: 0 | O25: =Sheet1!P25/Sheet1!$G$25 -> 1.5945028 | P25: =Sheet1!Q25/Sheet1!$G$25 -> 1.5271773 | Q25: =Sheet1!R25/Sheet1!$G$25 -> 1.5355158 | R25: SNU1 C24 | S25: 1
A26: 50000 | B26: =Sheet1!B26/Sheet1!$G$33 -> 0.010669775 | C26: =Sheet1!C26/Sheet1!$G$33 -> 0.012642338 | D26: =Sheet1!D26/Sheet1!$G$33 -> 0.013269972 | E26: SNU1 C111 | F26: 1 | H26: 50000 | I26: 0.010669775 | J26: 0.012642338 | K26: 0.013269972 | L26: SNU1 C111 | M26: 1 | N26: 50000 | O26: =Sheet1!P26/Sheet1!$G$33 -> 0 | P26: =Sheet1!Q26/Sheet1!$G$33 -> 0 | Q26: =Sheet1!R26/Sheet1!$G$33 -> 0 | R26: SNU1 C111 | S26: 1
A27: 12500 | B27: =Sheet1!B27/Sheet1!$G$33 -> 0.039182283 | C27: =Sheet1!C27/Sheet1!$G$33 -> 0.037299381 | D27: =Sheet1!D27/Sheet1!$G$33 -> 0.042051466 | E27: SNU1 C111 | F27: 1 | H27: 12500 | I27: 0.039182283 | J27: 0.037299381 | K27: 0.042051466 | L27: SNU1 C111 | M27: 1 | N27: 12500 | O27: =Sheet1!P27/Sheet1!$G$33 -> 0 | P27: =Sheet1!Q27/Sheet1!$G$33 -> 0 | Q27: =Sheet1!R27/Sheet1!$G$33 -> 0 | R27: SNU1 C111 | S27: 1
A28: 3125 | B28: =Sheet1!B28/Sheet1!$G$33 -> 0.0092351834 | C28: =Sheet1!C28/Sheet1!$G$33 -> 0.036223438 | D28: =Sheet1!D28/Sheet1!$G$33 -> 0.019635972 | E28: SNU1 C111 | F28: 1 | H28: 3125 | I28: 0.0092351834 | J28: 0.036223438 | K28: 0.019635972 | L28: SNU1 C111 | M28: 1 | N28: 3125 | O28: =Sheet1!P28/Sheet1!$G$33 -> 0 | P28: =Sheet1!Q28/Sheet1!$G$33 -> 0 | Q28: =Sheet1!R28/Sheet1!$G$33 -> 0 | R28: SNU1 C111 | S28: 1
A29: 781.25 | B29: =Sheet1!B29/Sheet1!$G$33 -> 0.011835381 | C29: =Sheet1!C29/Sheet1!$G$33 -> 0.0064556622 | D29: =Sheet1!D29/Sheet1!$G$33 -> 0.007083296 | E29: SNU1 C111 | F29: 1 | H29: 781.25 | I29: 0.011835381 | J29: 0.0064556622 | K29: 0.007083296 | L29: SNU1 C111 | M29: 1 | N29: 781.25 | O29: =Sheet1!P29/Sheet1!$G$33 -> 0 | P29: =Sheet1!Q29/Sheet1!$G$33 -> 0 | Q29: =Sheet1!R29/Sheet1!$G$33 -> 0 | R29: SNU1 C111 | S29: 1
A30: 195.3125 | B30: =Sheet1!B30/Sheet1!$G$33 -> 0.015870169 | C30: =Sheet1!C30/Sheet1!$G$33 -> 0.019187663 | D30: =Sheet1!D30/Sheet1!$G$33 -> 0.031202367 | E30: SNU1 C111 | F30: 1 | H30: 195.3125 | I30: 0.015870169 | J30: 0.019187663 | K30: 0.031202367 | L30: SNU1 C111 | M30: 1 | N30: 195.3125 | O30: =Sheet1!P30/Sheet1!$G$33 -> 0 | P30: =Sheet1!Q30/Sheet1!$G$33 -> 0 | Q30: =Sheet1!R30/Sheet1!$G$33 -> 0 | R30: SNU1 C111 | S30: 1
A31: 48.828125 | B31: =Sheet1!B31/Sheet1!$G$33 -> 0.22881736 | C31: =Sheet1!C31/Sheet1!$G$33 -> 0.073164171 | D31: =Sheet1!D31/Sheet1!$G$33 -> 0.14722496 | E31: SNU1 C111 | F31: 1 | H31: 48.828125 | I31: 0.22881736 | J31: 0.073164171 | K31: 0.14722496 | L31: SNU1 C111 | M31: 1 | N31: 48.828125 | O31: =Sheet1!P31/Sheet1!$G$33 -> 0 | P31: =Sheet1!Q31/Sheet1!$G$33 -> 0 | Q31: =Sheet1!R31/Sheet1!$G$33 -> 0 | R31: SNU1 C111 | S31: 1
A32: 12.207031 | B32: =Sheet1!B32/Sheet1!$G$33 -> 0.2489913 | C32: =Sheet1!C32/Sheet1!$G$33 -> 0.22003049 | D32: =Sheet1!D32/Sheet1!$G$33 -> 0.28611136 | E32: SNU1 C111 | F32: 1 | H32: 12.207031 | I32: 0.2489913 | J32: 0.22003049 | K32: 0.28611136 | L32: SNU1 C111 | M32: 1 | N32: 12.207031 | O32: =Sheet1!P32/Sheet1!$G$33 -> 0 | P32: =Sheet1!Q32/Sheet1!$G$33 -> 0 | Q32: =Sheet1!R32/Sheet1!$G$33 -> 0 | R32: SNU1 C111 | S32: 1
A33: 0 | B33: =Sheet1!B33/Sheet1!$G$33 -> 0.98206761 | C33: =Sheet1!C33/Sheet1!$G$33 -> 1.0339819 | D33: =Sheet1!D33/Sheet1!$G$33 -> 0.98395051 | E33: SNU1 C111 | F33: 1 | H33: 0 | I33: 0.98206761 | J33: 1.0339819 | K33: 0.98395051 | L33: SNU1 C111 | M33: 1 | N33: 0 | O33: =Sheet1!P33/Sheet1!$G$33 -> 0 | P33: =Sheet1!Q33/Sheet1!$G$33 -> 0 | Q33: =Sheet1!R33/Sheet1!$G$33 -> 0 | R33: SNU1 C111 | S33: 1
A34: 50000 | B34: =Sheet1!B34/Sheet1!$G$41 -> 0.020560796 | C34: =Sheet1!C34/Sheet1!$G$41 -> 0.021264398 | D34: =Sheet1!D34/Sheet1!$G$41 -> 0.021498932 | E34: SNU1 C114 | F34: 1 | H34: 50000 | I34: 0.020560796 | J34: 0.021264398 | K34: 0.021498932 | L34: SNU1 C114 | M34: 1 | N34: 50000 | O34: =Sheet1!P34/Sheet1!$G$41 -> 0 | P34: =Sheet1!Q34/Sheet1!$G$41 -> 0 | Q34: =Sheet1!R34/Sheet1!$G$41 -> 0 | R34: SNU1 C114 | S34: 1
A35: 12500 | B35: =Sheet1!B35/Sheet1!$G$41 -> 0.071298275 | C35: =Sheet1!C35/Sheet1!$G$41 -> 0.08169594 | D35: =Sheet1!D35/Sheet1!$G$41 -> 0.078647001 | E35: SNU1 C114 | F35: 1 | H35: 12500 | I35: 0.071298275 | J35: 0.08169594 | K35: 0.078647001 | L35: SNU1 C114 | M35: 1 | N35: 12500 | O35: =Sheet1!P35/Sheet1!$G$41 -> 0 | P35: =Sheet1!Q35/Sheet1!$G$41 -> 0 | Q35: =Sheet1!R35/Sheet1!$G$41 -> 0 | R35: SNU1 C114 | S35: 1
A36: 3125 | B36: =Sheet1!B36/Sheet1!$G$41 -> 0.086464794 | C36: =Sheet1!C36/Sheet1!$G$41 -> 0.091624537 | D36: =Sheet1!D36/Sheet1!$G$41 -> 0.1332152 | E36: SNU1 C114 | F36: 1 | H36: 3125 | I36: 0.086464794 | J36: 0.091624537 | K36: 0.1332152 | L36: SNU1 C114 | M36: 1 | N36: 3125 | O36: =Sheet1!P36/Sheet1!$G$41 -> 0 | P36: =Sheet1!Q36/Sheet1!$G$41 -> 0 | Q36: =Sheet1!R36/Sheet1!$G$41 -> 0 | R36: SNU1 C114 | S36: 1
A37: 781.25 | B37: =Sheet1!B37/Sheet1!$G$41 -> 0.1052275 | C37: =Sheet1!C37/Sheet1!$G$41 -> 0.087950175 | D37: =Sheet1!D37/Sheet1!$G$41 -> 0.1105436 | E37: SNU1 C114 | F37: 1 | H37: 781.25 | I37: 0.1052275 | J37: 0.087950175 | K37: 0.1105436 | L37: SNU1 C114 | M37: 1 | N37: 781.25 | O37: =Sheet1!P37/Sheet1!$G$41 -> 0 | P37: =Sheet1!Q37/Sheet1!$G$41 -> 0 | Q37: =Sheet1!R37/Sheet1!$G$41 -> 0 | R37: SNU1 C114 | S37: 1
A38: 195.3125 | B38: =Sheet1!B38/Sheet1!$G$41 -> 0.087793819 | C38: =Sheet1!C38/Sheet1!$G$41 -> 0.044014176 | D38: =Sheet1!D38/Sheet1!$G$41 -> 0.25368739 | E38: SNU1 C114 | F38: 1 | H38: 195.3125 | I38: 0.087793819 | J38: 0.044014176 | K38: 0.25368739 | L38: SNU1 C114 | M38: 1 | N38: 195.3125 | O38: =Sheet1!P38/Sheet1!$G$41 -> 0 | P38: =Sheet1!Q38/Sheet1!$G$41 -> 0 | Q38: =Sheet1!R38/Sheet1!$G$41 -> 0 | R38: SNU1 C114 | S38: 1
A39: 48.828125 | B39: =Sheet1!B39/Sheet1!$G$41 -> 0.33999583 | C39: =Sheet1!C39/Sheet1!$G$41 -> 0.29465263 | D39: =Sheet1!D39/Sheet1!$G$41 -> 0.3684526 | E39: SNU1 C114 | F39: 1 | H39: 48.828125 | I39: 0.33999583 | J39: 0.29465263 | K39: 0.3684526 | L39: SNU1 C114 | M39: 1 | N39: 48.828125 | O39: =Sheet1!P39/Sheet1!$G$41 -> 0 | P39: =Sheet1!Q39/Sheet1!$G$41 -> 0 | Q39: =Sheet1!R39/Sheet1!$G$41 -> 0 | R39: SNU1 C114 | S39: 1
A40: 12.207031 | B40: =Sheet1!B40/Sheet1!$G$41 -> 0.38432272 | C40: =Sheet1!C40/Sheet1!$G$41 -> 0.37666128 | D40: =Sheet1!D40/Sheet1!$G$41 -> 0.42833689 | E40: SNU1 C114 | F40: 1 | H40: 12.207031 | I40: 0.38432272 | J40: 0.37666128 | K40: 0.42833689 | L40: SNU1 C114 | M40: 1 | N40: 12.207031 | O40: =Sheet1!P40/Sheet1!$G$41 -> 0 | P40: =Sheet1!Q40/Sheet1!$G$41 -> 0 | Q40: =Sheet1!R40/Sheet1!$G$41 -> 0 | R40: SNU1 C114 | S40: 1
...

Sheet Sheet4
A1: Concentration (nM) | B1: Percent | C1: Cell line | D1: Run
A2: 50000 | B2: 0 | C2: SNU1 C12 | D2: 1
A3: 12500 | B3: 0 | C3: SNU1 C12 | D3: 1
A4: 3125 | B4: 0.08817278 | C4: SNU1 C12 | D4: 1
A5: 781.25 | B5: 0.083990401 | C5: SNU1 C12 | D5: 1
A6: 195.3125 | B6: 0.32910525 | C6: SNU1 C12 | D6: 1
A7: 48.828125 | B7: 0.60870758 | C7: SNU1 C12 | D7: 1
A8: 12.207031 | B8: 0.41652383 | C8: SNU1 C12 | D8: 1
A9: 0 | B9: 0.84072677 | C9: SNU1 C12 | D9: 1
A10: 50000 | B10: 0.060063676 | C10: SNU1 C13 | D10: 1
A11: 12500 | B11: 0.06649251 | C11: SNU1 C13 | D11: 1
A12: 3125 | B12: 0.035327973 | C12: SNU1 C13 | D12: 1
A13: 781.25 | B13: 0.042797665 | C13: SNU1 C13 | D13: 1
... A553: 0 | B553: 1.1125699 | C553: SNU1 C114 | D553: 5
